Workbook

Sheet DATA
A1: MBWAWA MISWE SECONDARY SCHOOL
A2: PERIODS & LESSON PLAN INSPECTION
B3: From | C3: Mond | D3: 09 | E3: FEB | F3: 2026
B4: To | C4: Thurs | D4: 13 | E4: FEB | F4: 2026
A5: SUBJECT | B5: TEACHER'S NAME | C5: CLASS | D5: NOP, NOL | E5: NOP Missing | F5: Comment | G5: NOLP Prepd | H5: Comment
A6: BIOLOGY | B6: Stela M | C6: F1 | D6: =OUTPUT!D7&" , "&OUTPUT!H7 -> 6 , 4
B7: Stela M | C7: F2 | D7: =OUTPUT!D8&" , "&OUTPUT!H8 -> 6 , 4
B8: Muna A | C8: F3 | D8: =OUTPUT!D9&" , "&OUTPUT!H9 -> 8 , 4
B9: Muna A | C9: F4 | D9: =OUTPUT!D10&" , "&OUTPUT!H10 -> 8 , 4
A10: CHEMISTRY | B10: Shedi O | C10: F1 | D10: =OUTPUT!D11&" , "&OUTPUT!H11 -> 6 , 4
B11: Shedi O | C11: F2 | D11: =OUTPUT!D12&" , "&OUTPUT!H12 -> 3 , 2
B12: Shedi O | C12: F3 | D12: =OUTPUT!D13&" , "&OUTPUT!H13 -> 4 , 2
B13: Shedi O | C13: F4 | D13: =OUTPUT!D14&" , "&OUTPUT!H14 -> 4 , 2
A14: PHYSICS | B14: Baraka W | C14: F1 | D14: =OUTPUT!D15&" , "&OUTPUT!H15 -> 6 , 4
B15: Baraka W | C15: F2 | D15: =OUTPUT!D16&" , "&OUTPUT!H16 -> 3 , 2
B16: Annastazia F | C16: F3 | D16: =OUTPUT!D17&" , "&OUTPUT!H17 -> 4 , 2
B17: Annastazia F | C17: F4 | D17: =OUTPUT!D18&" , "&OUTPUT!H18 -> 4 , 2
A18: B.MATHS | B18: Andrew M | C18: F1 | D18: =OUTPUT!D19&" , "&OUTPUT!H19 -> 12 , 6
B19: Andrew M | C19: F2 | D19: =OUTPUT!D20&" , "&OUTPUT!H20 -> 12 , 6
B20: Aneth D | C20: F3 | D20: =OUTPUT!D21&" , "&OUTPUT!H21 -> 12 , 6
B21: Aneth D | C21: F4 | D21: =OUTPUT!D22&" , "&OUTPUT!H22 -> 12 , 6
A22: ENGLISH | B22: Sarah M | C22: F1 | D22: =OUTPUT!D23&" , "&OUTPUT!H23 -> 12 , 6
B23: Singo MJ | C23: F2 | D23: =OUTPUT!D24&" , "&OUTPUT!H24 -> 12 , 6
B24: Singo MJ | C24: F3 | D24: =OUTPUT!D25&" , "&OUTPUT!H25 -> 12 , 6
B25: Lawi W | C25: F4 | D25: =OUTPUT!D26&" , "&OUTPUT!H26 -> 12 , 6
A26: HISTORY | B26: Gwamaka M | C26: F1 | D26: =OUTPUT!D27&" , "&OUTPUT!H27 -> 6 , 4
B27: Gwamaka M | C27: F2 | D27: =OUTPUT!D28&" , "&OUTPUT!H28 -> 3 , 2
B28: Anna ND | C28: F3 | D28: =OUTPUT!D29&" , "&OUTPUT!H29 -> 6 , 4
B29: Anna ND | C29: F4 | D29: =OUTPUT!D30&" , "&OUTPUT!H30 -> 6 , 4
A30: GEOGRAPHY | B30: Oliver K | C30: F1 | D30: =OUTPUT!D31&" , "&OUTPUT!H31 -> 6 , 4
B31: Johnson P | C31: F2 | D31: =OUTPUT!D32&" , "&OUTPUT!H32 -> 6 , 4
B32: Bunuasi M | C32: F3 | D32: =OUTPUT!D33&" , "&OUTPUT!H33 -> 6 , 4
B33: Bunuasi M | C33: F4 | D33: =OUTPUT!D34&" , "&OUTPUT!H34 -> 6 , 4
A34: KISWAHILI | B34: Goodluck M | C34: F1 | D34: =OUTPUT!D35&" , "&OUTPUT!H35 -> 6 , 4
B35: Henry H | C35: F2 | D35: =OUTPUT!D36&" , "&OUTPUT!H36 -> 6 , 4
B36: Goodluck M | C36: F3 | D36: =OUTPUT!D37&" , "&OUTPUT!H37 -> 6 , 4
B37: Hashim K | C37: F4 | D37: =OUTPUT!D38&" , "&OUTPUT!H38 -> 6 , 4
A38: EDK | B38: Bakari S | C38: F1 | D38: =OUTPUT!D39&" , "&OUTPUT!H39 -> 4 , 2
B39: Mbawala K | C39: F2 | D39: =OUTPUT!D40&" , "&OUTPUT!H40 -> 4 , 2
B40: Mbawala K | C40: F3 | D40: =OUTPUT!D41&" , "&OUTPUT!H41 -> 4 , 2
...

Sheet OUTPUT
A1: MBWAWA MISWE SECONDARY SCHOOL
A2: ACADEMIC DEPARTMENT
A3: WEEKLY PERIODS & LESSON PLAN INSPECTION
G4: From | H4: =DATA!C3 -> Mond | I4: =DATA!D3 -> 09 | J4: =DATA!E3 -> FEB | K4: =DATA!F3 -> 2026
G5: To | H5: =DATA!C4 -> Thurs | I5: =DATA!D4 -> 13 | J5: =DATA!E4 -> FEB | K5: =DATA!F4 -> 2026
A6: SUBJECT | B6: TEACHER'S NAME | C6: CLASS | D6: NO Period | E6: NOP Taught | F6: NOPT% | G6: Comment | H6: NOL Plan | I6: NOLP Prepd | J6: NOLPP% | K6: Comment
A7: BIOLOGY | B7: =DATA!B6 -> Stela M | C7: F1 | D7: 6 | E7: =D7-DATA!E6 -> 6 | F7: =E7/D7*100 -> 100 | G7: =IF(ISBLANK(DATA!F6),"",DATA!F6) | H7: 4 | I7: =DATA!G6 -> 0 | J7: =I7/H7*100 -> 0 | K7: =IF(ISBLANK(DATA!H6),"",DATA!H6)
B8: =DATA!B7 -> Stela M | C8: F2 | D8: 6 | E8: =D8-DATA!E7 -> 6 | F8: =E8/D8*100 -> 100 | G8: =IF(ISBLANK(DATA!F7),"",DATA!F7) | H8: 4 | I8: =DATA!G7 -> 0 | J8: =I8/H8*100 -> 0 | K8: =IF(ISBLANK(DATA!H7),"",DATA!H7)
B9: =DATA!B8 -> Muna A | C9: F3 | D9: 8 | E9: =D9-DATA!E8 -> 8 | F9: =E9/D9*100 -> 100 | G9: =IF(ISBLANK(DATA!F8),"",DATA!F8) | H9: 4 | I9: =DATA!G8 -> 0 | J9: =I9/H9*100 -> 0 | K9: =IF(ISBLANK(DATA!H8),"",DATA!H8)
B10: =DATA!B9 -> Muna A | C10: F4 | D10: 8 | E10: =D10-DATA!E9 -> 8 | F10: =E10/D10*100 -> 100 | G10: =IF(ISBLANK(DATA!F9),"",DATA!F9) | H10: 4 | I10: =DATA!G9 -> 0 | J10: =I10/H10*100 -> 0 | K10: =IF(ISBLANK(DATA!H9),"",DATA!H9)
A11: CHEMISTRY | B11: =DATA!B10 -> Shedi O | C11: F1 | D11: 6 | E11: =D11-DATA!E10 -> 6 | F11: =E11/D11*100 -> 100 | G11: =IF(ISBLANK(DATA!F10),"",DATA!F10) | H11: 4 | I11: =DATA!G10 -> 0 | J11: =I11/H11*100 -> 0 | K11: =IF(ISBLANK(DATA!H10),"",DATA!H10)
B12: =DATA!B11 -> Shedi O | C12: F2 | D12: 3 | E12: =D12-DATA!E11 -> 3 | F12: =E12/D12*100 -> 100 | G12: =IF(ISBLANK(DATA!F11),"",DATA!F11) | H12: 2 | I12: =DATA!G11 -> 0 | J12: =I12/H12*100 -> 0 | K12: =IF(ISBLANK(DATA!H11),"",DATA!H11)
B13: =DATA!B12 -> Shedi O | C13: F3 | D13: 4 | E13: =D13-DATA!E12 -> 4 | F13: =E13/D13*100 -> 100 | G13: =IF(ISBLANK(DATA!F12),"",DATA!F12) | H13: 2 | I13: =DATA!G12 -> 0 | J13: =I13/H13*100 -> 0 | K13: =IF(ISBLANK(DATA!H12),"",DATA!H12)
B14: =DATA!B13 -> Shedi O | C14: F4 | D14: 4 | E14: =D14-DATA!E13 -> 4 | F14: =E14/D14*100 -> 100 | G14: =IF(ISBLANK(DATA!F13),"",DATA!F13) | H14: 2 | I14: =DATA!G13 -> 0 | J14: =I14/H14*100 -> 0 | K14: =IF(ISBLANK(DATA!H13),"",DATA!H13)
A15: PHYSICS | B15: =DATA!B14 -> Baraka W | C15: F1 | D15: 6 | E15: =D15-DATA!E14 -> 6 | F15: =E15/D15*100 -> 100 | G15: =IF(ISBLANK(DATA!F14),"",DATA!F14) | H15: 4 | I15: =DATA!G14 -> 0 | J15: =I15/H15*100 -> 0 | K15: =IF(ISBLANK(DATA!H14),"",DATA!H14)
B16: =DATA!B15 -> Baraka W | C16: F2 | D16: 3 | E16: =D16-DATA!E15 -> 3 | F16: =E16/D16*100 -> 100 | G16: =IF(ISBLANK(DATA!F15),"",DATA!F15) | H16: 2 | I16: =DATA!G15 -> 0 | J16: =I16/H16*100 -> 0 | K16: =IF(ISBLANK(DATA!H15),"",DATA!H15)
B17: =DATA!B16 -> Annastazia F | C17: F3 | D17: 4 | E17: =D17-DATA!E16 -> 4 | F17: =E17/D17*100 -> 100 | G17: =IF(ISBLANK(DATA!F16),"",DATA!F16) | H17: 2 | I17: =DATA!G16 -> 0 | J17: =I17/H17*100 -> 0 | K17: =IF(ISBLANK(DATA!H16),"",DATA!H16)
B18: =DATA!B17 -> Annastazia F | C18: F4 | D18: 4 | E18: =D18-DATA!E17 -> 4 | F18: =E18/D18*100 -> 100 | G18: =IF(ISBLANK(DATA!F17),"",DATA!F17) | H18: 2 | I18: =DATA!G17 -> 0 | J18: =I18/H18*100 -> 0 | K18: =IF(ISBLANK(DATA!H17),"",DATA!H17)
A19: B.MATHS | B19: =DATA!B18 -> Andrew M | C19: F1 | D19: 12 | E19: =D19-DATA!E18 -> 12 | F19: =E19/D19*100 -> 100 | G19: =IF(ISBLANK(DATA!F18),"",DATA!F18) | H19: 6 | I19: =DATA!G18 -> 0 | J19: =I19/H19*100 -> 0 | K19: =IF(ISBLANK(DATA!H18),"",DATA!H18)
B20: =DATA!B19 -> Andrew M | C20: F2 | D20: 12 | E20: =D20-DATA!E19 -> 12 | F20: =E20/D20*100 -> 100 | G20: =IF(ISBLANK(DATA!F19),"",DATA!F19) | H20: 6 | I20: =DATA!G19 -> 0 | J20: =I20/H20*100 -> 0 | K20: =IF(ISBLANK(DATA!H19),"",DATA!H19)
B21: =DATA!B20 -> Aneth D | C21: F3 | D21: 12 | E21: =D21-DATA!E20 -> 12 | F21: =E21/D21*100 -> 100 | G21: =IF(ISBLANK(DATA!F20),"",DATA!F20) | H21: 6 | I21: =DATA!G20 -> 0 | J21: =I21/H21*100 -> 0 | K21: =IF(ISBLANK(DATA!H20),"",DATA!H20)
B22: =DATA!B21 -> Aneth D | C22: F4 | D22: 12 | E22: =D22-DATA!E21 -> 12 | F22: =E22/D22*100 -> 100 | G22: =IF(ISBLANK(DATA!F21),"",DATA!F21) | H22: 6 | I22: =DATA!G21 -> 0 | J22: =I22/H22*100 -> 0 | K22: =IF(ISBLANK(DATA!H21),"",DATA!H21)
A23: ENGLISH | B23: =DATA!B22 -> Sarah M | C23: F1 | D23: 12 | E23: =D23-DATA!E22 -> 12 | F23: =E23/D23*100 -> 100 | G23: =IF(ISBLANK(DATA!F22),"",DATA!F22) | H23: 6 | I23: =DATA!G22 -> 0 | J23: =I23/H23*100 -> 0 | K23: =IF(ISBLANK(DATA!H22),"",DATA!H22)
B24: =DATA!B23 -> Singo MJ | C24: F2 | D24: 12 | E24: =D24-DATA!E23 -> 12 | F24: =E24/D24*100 -> 100 | G24: =IF(ISBLANK(DATA!F23),"",DATA!F23) | H24: 6 | I24: =DATA!G23 -> 0 | J24: =I24/H24*100 -> 0 | K24: =IF(ISBLANK(DATA!H23),"",DATA!H23)
B25: =DATA!B24 -> Singo MJ | C25: F3 | D25: 12 | E25: =D25-DATA!E24 -> 12 | F25: =E25/D25*100 -> 100 | G25: =IF(ISBLANK(DATA!F24),"",DATA!F24) | H25: 6 | I25: =DATA!G24 -> 0 | J25: =I25/H25*100 -> 0 | K25: =IF(ISBLANK(DATA!H24),"",DATA!H24)
B26: =DATA!B25 -> Lawi W | C26: F4 | D26: 12 | E26: =D26-DATA!E25 -> 12 | F26: =E26/D26*100 -> 100 | G26: =IF(ISBLANK(DATA!F25),"",DATA!F25) | H26: 6 | I26: =DATA!G25 -> 0 | J26: =I26/H26*100 -> 0 | K26: =IF(ISBLANK(DATA!H25),"",DATA!H25)
A27: HISTORY | B27: =DATA!B26 -> Gwamaka M | C27: F1 | D27: 6 | E27: =D27-DATA!E26 -> 6 | F27: =E27/D27*100 -> 100 | G27: =IF(ISBLANK(DATA!F26),"",DATA!F26) | H27: 4 | I27: =DATA!G26 -> 0 | J27: =I27/H27*100 -> 0 | K27: =IF(ISBLANK(DATA!H26),"",DATA!H26)
B28: =DATA!B27 -> Gwamaka M | C28: F2 | D28: 3 | E28: =D28-DATA!E27 -> 3 | F28: =E28/D28*100 -> 100 | G28: =IF(ISBLANK(DATA!F27),"",DATA!F27) | H28: 2 | I28: =DATA!G27 -> 0 | J28: =I28/H28*100 -> 0 | K28: =IF(ISBLANK(DATA!H27),"",DATA!H27)
B29: =DATA!B28 -> Anna ND | C29: F3 | D29: 6 | E29: =D29-DATA!E28 -> 6 | F29: =E29/D29*100 -> 100 | G29: =IF(ISBLANK(DATA!F28),"",DATA!F28) | H29: 4 | I29: =DATA!G28 -> 0 | J29: =I29/H29*100 -> 0 | K29: =IF(ISBLANK(DATA!H28),"",DATA!H28)
B30: =DATA!B29 -> Anna ND | C30: F4 | D30: 6 | E30: =D30-DATA!E29 -> 6 | F30: =E30/D30*100 -> 100 | G30: =IF(ISBLANK(DATA!F29),"",DATA!F29) | H30: 4 | I30: =DATA!G29 -> 0 | J30: =I30/H30*100 -> 0 | K30: =IF(ISBLANK(DATA!H29),"",DATA!H29)
A31: GEOGRAPHY | B31: =DATA!B30 -> Oliver K | C31: F1 | D31: 6 | E31: =D31-DATA!E30 -> 6 | F31: =E31/D31*100 -> 100 | G31: =IF(ISBLANK(DATA!F30),"",DATA!F30) | H31: 4 | I31: =DATA!G30 -> 0 | J31: =I31/H31*100 -> 0 | K31: =IF(ISBLANK(DATA!H30),"",DATA!H30)
B32: =DATA!B31 -> Johnson P | C32: F2 | D32: 6 | E32: =D32-DATA!E31 -> 6 | F32: =E32/D32*100 -> 100 | G32: =IF(ISBLANK(DATA!F31),"",DATA!F31) | H32: 4 | I32: =DATA!G31 -> 0 | J32: =I32/H32*100 -> 0 | K32: =IF(ISBLANK(DATA!H31),"",DATA!H31)
B33: =DATA!B32 -> Bunuasi M | C33: F3 | D33: 6 | E33: =D33-DATA!E32 -> 6 | F33: =E33/D33*100 -> 100 | G33: =IF(ISBLANK(DATA!F32),"",DATA!F32) | H33: 4 | I33: =DATA!G32 -> 0 | J33: =I33/H33*100 -> 0 | K33: =IF(ISBLANK(DATA!H32),"",DATA!H32)
B34: =DATA!B33 -> Bunuasi M | C34: F4 | D34: 6 | E34: =D34-DATA!E33 -> 6 | F34: =E34/D34*100 -> 100 | G34: =IF(ISBLANK(DATA!F33),"",DATA!F33) | H34: 4 | I34: =DATA!G33 -> 0 | J34: =I34/H34*100 -> 0 | K34: =IF(ISBLANK(DATA!H33),"",DATA!H33)
A35: KISWAHILI | B35: =DATA!B34 -> Goodluck M | C35: F1 | D35: 6 | E35: =D35-DATA!E34 -> 6 | F35: =E35/D35*100 -> 100 | G35: =IF(ISBLANK(DATA!F34),"",DATA!F34) | H35: 4 | I35: =DATA!G34 -> 0 | J35: =I35/H35*100 -> 0 | K35: =IF(ISBLANK(DATA!H34),"",DATA!H34)
B36: =DATA!B35 -> Henry H | C36: F2 | D36: 6 | E36: =D36-DATA!E35 -> 6 | F36: =E36/D36*100 -> 100 | G36: =IF(ISBLANK(DATA!F35),"",DATA!F35) | H36: 4 | I36: =DATA!G35 -> 0 | J36: =I36/H36*100 -> 0 | K36: =IF(ISBLANK(DATA!H35),"",DATA!H35)
B37: =DATA!B36 -> Goodluck M | C37: F3 | D37: 6 | E37: =D37-DATA!E36 -> 6 | F37: =E37/D37*100 -> 100 | G37: =IF(ISBLANK(DATA!F36),"",DATA!F36) | H37: 4 | I37: =DATA!G36 -> 0 | J37: =I37/H37*100 -> 0 | K37: =IF(ISBLANK(DATA!H36),"",DATA!H36)
B38: =DATA!B37 -> Hashim K | C38: F4 | D38: 6 | E38: =D38-DATA!E37 -> 6 | F38: =E38/D38*100 -> 100 | G38: =IF(ISBLANK(DATA!F37),"",DATA!F37) | H38: 4 | I38: =DATA!G37 -> 0 | J38: =I38/H38*100 -> 0 | K38: =IF(ISBLANK(DATA!H37),"",DATA!H37)
A39: EDK | B39: =DATA!B38 -> Bakari S | C39: F1 | D39: 4 | E39: =D39-DATA!E38 -> 4 | F39: =E39/D39*100 -> 100 | G39: =IF(ISBLANK(DATA!F38),"",DATA!F38) | H39: 2 | I39: =DATA!G38 -> 0 | J39: =I39/H39*100 -> 0 | K39: =IF(ISBLANK(DATA!H38),"",DATA!H38)
B40: =DATA!B39 -> Mbawala K | C40: F2 | D40: 4 | E40: =D40-DATA!E39 -> 4 | F40: =E40/D40*100 -> 100 | G40: =IF(ISBLANK(DATA!F39),"",DATA!F39) | H40: 2 | I40: =DATA!G39 -> 0 | J40: =I40/H40*100 -> 0 | K40: =IF(ISBLANK(DATA!H39),"",DATA!H39)
...
